<?xml version="1.0" ?>
<sdf version="1.8">
  <world name="simple_world">
    <physics name="1ms" type="ignored">
      <max_step_size>0.001</max_step_size>
      <real_time_factor>1.0</real_time_factor>
    </physics>

    <plugin filename="gz-sim-physics-system" name="gz::sim::systems::Physics"/>
    <plugin filename="gz-sim-scene-broadcaster-system" name="gz::sim::systems::SceneBroadcaster"/>
    <plugin filename="gz-sim-user-commands-system" name="gz::sim::systems::UserCommands"/>
    <plugin filename="gz-sim-sensors-system" name="gz::sim::systems::Sensors"/>
    <plugin filename="gz-sim-imu-system" name="gz::sim::systems::Imu" />

    <light type="directional" name="sun">
      <cast_shadows>true</cast_shadows>
      <pose>0 0 10 0 0 0</pose>
      <diffuse>0.8 0.8 0.8 1</diffuse>
      <specular>0.2 0.2 0.2 1</specular>
      <attenuation>
        <range>1000</range>
        <constant>0.9</constant>
        <linear>0.01</linear>
        <quadratic>0.001</quadratic>
      </attenuation>
      <direction>-0.5 0.1 -0.9</direction>
    </light>

    <model name="ground_plane">
      <static>true</static>
      <link name="link">
        <collision name="collision">
          <pose>10 0 0 1.57 0 3.14</pose>
          <geometry>
            <mesh>
              <uri>field2025.obj</uri>
              <scale>1 1 1</scale>
            </mesh>
          </geometry>
          <surface>
            <friction>
              <ode>
                <mu>1.0</mu>       <!-- 摩擦係数（静止） -->
                <mu2>1.0</mu2>     <!-- 摩擦係数（動摩擦） -->
              </ode>
            </friction>
            <contact>
              <ode>
                <kp>100</kp>       <!-- バネ定数：硬さ -->
                <kd>1.0</kd>       <!-- ダンパー：跳ね返り抑える -->
              </ode>
            </contact>
          </surface>
        </collision>
        <visual name="visual">
          <pose>10 0 0 1.57 0 3.14</pose>
          <geometry>
            <mesh>
              <uri>field2025.obj</uri>
              <scale>1 1 1</scale>
            </mesh>
          </geometry>
        </visual>
      </link>
    </model>

    <model name="Robot">
      <static>false</static>
      <pose>-0.1 -0.65 0.1 0 0 0</pose>

      <link name="base_link">
        <inertial>
          <mass>1.0</mass>  
          <inertia>    
              <ixx>0.0835</ixx>
              <ixy>0</ixy>
              <ixz>0</ixz>
              <iyy>0.1209</iyy>
              <iyz>0</iyz>
              <izz>0.1209</izz>
          </inertia>
      </inertial>
        <visual name="visual">
          <geometry><box><size>0.3 0.3 0.1</size></box></geometry>
          <material><ambient>0 0 1 1</ambient><diffuse>0 0 1 1</diffuse></material>
        </visual>
        <collision name="collision">
          <geometry><box><size>0.5 0.3 0.1</size></box></geometry>
        </collision>

        <sensor name="lidar" type="gpu_lidar">
          <pose>0.4 0 0.0 0 0 0</pose>
          <topic>lidar</topic>
          <update_rate>10</update_rate>
          <lidar>
              <scan>
                  <horizontal>
                      <samples>360</samples>
                      <resolution>1</resolution>
                      <min_angle>-3.14</min_angle>
                      <max_angle>3.14</max_angle>
                  </horizontal>
              </scan>
              <range>
                  <min>0.02</min>
                  <max>12.0</max>
                  <resolution>0.01</resolution>
              </range>
              <noise>
                  <type>gaussian</type>
                  <mean>0.0</mean>
                  <stddev>0.01</stddev>
              </noise>
          </lidar>
          <visualize>true</visualize>
          <always_on>1</always_on>
        </sensor>

        <sensor name="imu_sensor" type="imu">
          <always_on>1</always_on>
          <update_rate>500</update_rate>
          <visualize>true</visualize>
          <topic>/imu</topic>
        </sensor>
      </link>

      <link name="left_wheel">
        <pose relative_to="base_link">0.15 0.175 0 -1.5708 0 0</pose>    <!-- 左車輪の位置 -->
        <inertial>
            <mass>0.5</mass>    <!-- 車輪の質量 -->
            <inertia>
                <ixx>0.00125</ixx>
                <ixy>0</ixy>
                <ixz>0</ixz>
                <iyy>0.00125</iyy>
                <iyz>0</iyz>
                <izz>0.002</izz>
            </inertia>
        </inertial>
        <visual name="visual">
            <geometry>
                <cylinder>
                    <radius>0.1</radius>    <!-- 車輪の半径 -->
                    <length>0.05</length>    <!-- 車輪の幅 -->
                </cylinder>
            </geometry>
            <material>
                <ambient>0 0 0 1</ambient>    <!-- 黒色 -->
                <diffuse>0 0 0 1</diffuse>
                <specular>0 0 0 1</specular>
            </material>
        </visual>
        <collision name="collision">
            <geometry>
                <cylinder>
                    <radius>0.1</radius>
                    <length>0.05</length>
                </cylinder>
            </geometry>
        </collision>
      </link>

      <link name="right_wheel">
        <pose relative_to="base_link">0.15 -0.175 0 -1.5708 0 0</pose>    <!-- 右車輪の位置 -->
        <inertial>
            <mass>0.5</mass>
            <inertia>
                <ixx>0.00125</ixx>
                <ixy>0</ixy>
                <ixz>0</ixz>
                <iyy>0.00125</iyy>
                <iyz>0</iyz>
                <izz>0.002</izz>
            </inertia>
        </inertial>
        <visual name="visual">
            <geometry>
                <cylinder>
                    <radius>0.1</radius>
                    <length>0.05</length>
                </cylinder>
            </geometry>
            <material>
                <ambient>0 0 0 1</ambient>
                <diffuse>0 0 0 1</diffuse>
                <specular>0 0 0 1</specular>
            </material>
        </visual>
        <collision name="collision">
            <geometry>
                <cylinder>
                    <radius>0.1</radius>
                    <length>0.05</length>
                </cylinder>
            </geometry>
        </collision>
      </link>

      <link name="left_wheel_b">
        <pose relative_to="base_link">-0.15 0.175 0 -1.5708 0 0</pose>    <!-- 左車輪の位置 -->
        <inertial>
            <mass>0.5</mass>    <!-- 車輪の質量 -->
            <inertia>
                <ixx>0.00125</ixx>
                <ixy>0</ixy>
                <ixz>0</ixz>
                <iyy>0.00125</iyy>
                <iyz>0</iyz>
                <izz>0.002</izz>
            </inertia>
        </inertial>
        <visual name="visual">
            <geometry>
                <cylinder>
                    <radius>0.1</radius>    <!-- 車輪の半径 -->
                    <length>0.05</length>    <!-- 車輪の幅 -->
                </cylinder>
            </geometry>
            <material>
                <ambient>0 0 0 1</ambient>    <!-- 黒色 -->
                <diffuse>0 0 0 1</diffuse>
                <specular>0 0 0 1</specular>
            </material>
        </visual>
        <collision name="collision">
            <geometry>
                <cylinder>
                    <radius>0.1</radius>
                    <length>0.05</length>
                </cylinder>
            </geometry>
        </collision>
      </link>

      <link name="right_wheel_b">
        <pose relative_to="base_link">-0.15 -0.175 0 -1.5708 0 0</pose>    <!-- 右車輪の位置 -->
        <inertial>
            <mass>0.5</mass>
            <inertia>
                <ixx>0.00125</ixx>
                <ixy>0</ixy>
                <ixz>0</ixz>
                <iyy>0.00125</iyy>
                <iyz>0</iyz>
                <izz>0.002</izz>
            </inertia>
        </inertial>
        <visual name="visual">
            <geometry>
                <cylinder>
                    <radius>0.1</radius>
                    <length>0.05</length>
                </cylinder>
            </geometry>
            <material>
                <ambient>0 0 0 1</ambient>
                <diffuse>0 0 0 1</diffuse>
                <specular>0 0 0 1</specular>
            </material>
        </visual>
        <collision name="collision">
            <geometry>
                <cylinder>
                    <radius>0.1</radius>
                    <length>0.05</length>
                </cylinder>
            </geometry>
        </collision>
      </link>

      

      <joint name="left_wheel_joint" type="revolute">
        <parent>base_link</parent>
        <child>left_wheel</child>
        <axis>
            <xyz>0 0 1</xyz>    <!-- 回転軸 -->
            <limit>
                <lower>-1.79769e+308</lower>    <!-- 回転制限なし -->
                <upper>1.79769e+308</upper>
            </limit>
        </axis>
      </joint>

      <!-- 右車輪のジョイント -->
      <joint name="right_wheel_joint" type="revolute">
          <parent>base_link</parent>
          <child>right_wheel</child>
          <axis>
              <xyz>0 0 1</xyz>
              <limit>
                  <lower>-1.79769e+308</lower>
                  <upper>1.79769e+308</upper>
              </limit>
          </axis>
      </joint>

      <joint name="left_wheel_joint_b" type="revolute">
        <parent>base_link</parent>
        <child>left_wheel_b</child>
        <axis>
            <xyz>0 0 1</xyz>    <!-- 回転軸 -->
            <limit>
                <lower>-1.79769e+308</lower>    <!-- 回転制限なし -->
                <upper>1.79769e+308</upper>
            </limit>
        </axis>
      </joint>

      <!-- 右車輪のジョイント -->
      <joint name="right_wheel_joint_b" type="revolute">
          <parent>base_link</parent>
          <child>right_wheel_b</child>
          <axis>
              <xyz>0 0 1</xyz>
              <limit>
                  <lower>-1.79769e+308</lower>
                  <upper>1.79769e+308</upper>
              </limit>
          </axis>
      </joint>


      <plugin filename="gz-sim-diff-drive-system" name="gz::sim::systems::DiffDrive">
        <topic>cmd_vel</topic>    
        <left_joint>left_wheel_joint</left_joint>   
        <right_joint>right_wheel_joint</right_joint>  
        <wheel_separation>0.35</wheel_separation>   
        <wheel_radius>0.1</wheel_radius> 
      </plugin>

      <plugin filename="gz-sim-diff-drive-system" name="gz::sim::systems::DiffDrive">
        <topic>cmd_vel</topic>    
        <left_joint>left_wheel_joint_b</left_joint>   
        <right_joint>right_wheel_joint_b</right_joint>  
        <wheel_separation>0.35</wheel_separation>   
        <wheel_radius>0.1</wheel_radius> 
      </plugin>
    </model>
  </world>
</sdf>
